
#######################################################################
# +-----------------------------------------------------------------+ #
# |                            BO3 object                           | #
# +-----------------------------------------------------------------+ #
#######################################################################

Author: Unknown

Description: Converted version of the BO2 OakForestSmall12

Version: 3

SettingsMode: WriteWithoutComments


#######################################################################
# +-----------------------------------------------------------------+ #
# |                          Main settings                          | #
# +-----------------------------------------------------------------+ #
#######################################################################

Tree: true

Frequency: 1

Rarity: 10.0

RotateRandomly: true

SpawnHeight: highestSolidBlock

SpawnHeightOffset: 0

SpawnHeightVariance: 0

##############################
# Height Limits for the BO3. #
##############################

MinHeight: 62

MaxHeight: 210

######################
# Extrusion settings #
######################

ExtrudeMode: None

ExtrudeThroughBlocks: AIR

MaxBranchDepth: 10

ExcludedBiomes: All


#######################################################################
# +-----------------------------------------------------------------+ #
# |                      Source block settings                      | #
# +-----------------------------------------------------------------+ #
#######################################################################

SourceBlocks: STONE:1,STONE:3,STONE:5,DIRT:1,DIRT:0,SAND:0,GRASS:0,DIRT:2,STATIONARY_WATER:0,HARD_CLAY,STAINED_CLAY:0,CLAY,SANDSTONE:0,SAND:1,AIR,STONE:0,GRAVEL,LONG_GRASS:0,LONG_GRASS:1,LONG_GRASS:2,DEAD_BUSH,YELLOW_FLOWER:0,RED_ROSE:0,BROWN_MUSHROOM,RED_MUSHROOM

MaxPercentageOutsideSourceBlock: 0

OutsideSourceBlock: placeAnyway

IsOTGPlus: false


#######################################################################
# +-----------------------------------------------------------------+ #
# |                              Blocks                             | #
# +-----------------------------------------------------------------+ #
#######################################################################

Block(1,9,4,LEAVES:0)
Block(1,8,-4,LEAVES:0)
Block(2,9,2,LOG:0)
Block(2,8,2,LEAVES:0)
Block(1,9,-4,LEAVES:0)
Block(1,7,-4,LEAVES:0)
Block(-4,12,-1,LEAVES:0)
Block(-3,10,2,LEAVES:0)
Block(-4,11,-1,LOG:0)
Block(-4,10,-1,LOG:0)
Block(-1,5,0,LOG:8)
Block(3,8,0,LEAVES:0)
Block(-1,7,0,LOG:0)
Block(-3,12,2,LEAVES:0)
Block(-1,6,0,LOG:0)
Block(-3,11,2,LEAVES:0)
Block(-1,9,0,LOG:0)
Block(-1,8,0,LOG:0)
Block(3,9,0,LOG:0)
Block(-1,9,-3,LEAVES:0)
Block(-1,8,-3,LEAVES:0)
Block(-2,10,-3,LEAVES:0)
Block(-1,7,-3,LEAVES:0)
Block(-1,6,-3,LEAVES:0)
Block(-3,5,-2,LEAVES:0)
Block(-3,6,-2,LEAVES:0)
Block(1,10,1,LEAVES:0)
Block(-3,7,-2,LEAVES:0)
Block(1,11,1,LEAVES:0)
Block(-3,8,-2,LEAVES:0)
Block(-3,9,-2,LEAVES:0)
Block(3,10,2,LEAVES:0)
Block(3,11,2,LEAVES:0)
Block(0,5,-1,LEAVES:0)
Block(0,7,-1,LEAVES:0)
Block(0,6,-1,LEAVES:0)
Block(0,8,-1,LEAVES:0)
Block(1,9,-3,LEAVES:0)
Block(2,9,3,LEAVES:0)
Block(1,10,2,LEAVES:0)
Block(1,6,-3,LEAVES:0)
Block(1,11,2,LEAVES:0)
Block(0,10,3,LEAVES:0)
Block(0,11,3,LEAVES:0)
Block(1,11,-1,LEAVES:0)
Block(1,10,-1,LEAVES:0)
Block(-1,6,-2,LOG:8)
Block(3,9,1,LEAVES:0)
Block(-1,9,-2,LEAVES:0)
Block(-1,8,-2,LEAVES:0)
Block(-1,7,-2,LEAVES:0)
Block(-2,11,4,LEAVES:0)
Block(-1,10,-4,LEAVES:0)
Block(-2,10,4,LEAVES:0)
Block(-3,5,-1,LOG:0)
Block(-3,6,-1,LOG:0)
Block(-3,7,-1,LOG:0)
Block(-3,8,-1,LOG:0)
Block(-3,9,-1,LEAVES:0)
Block(-1,10,2,LEAVES:0)
Block(0,10,-1,LEAVES:0)
Block(-1,12,2,LEAVES:0)
Block(-1,11,2,LEAVES:0)
Block(0,12,-1,LEAVES:0)
Block(0,11,-1,LEAVES:0)
Block(0,14,-1,LEAVES:0)
Block(0,13,-1,LEAVES:0)
Block(0,5,0,LOG:4)
Block(0,7,0,LEAVES:0)
Block(0,6,0,LEAVES:0)
Block(1,8,-2,LEAVES:0)
Block(1,9,-2,LOG:0)
Block(-4,8,-1,LEAVES:0)
Block(-4,7,-1,LEAVES:0)
Block(-4,9,-1,LOG:0)
Block(-1,7,2,LOG:0)
Block(2,10,3,LEAVES:0)
Block(-1,6,2,LEAVES:0)
Block(3,9,2,LEAVES:0)
Block(2,11,3,LEAVES:0)
Block(-4,6,-1,LEAVES:0)
Block(-1,9,2,LEAVES:0)
Block(-4,5,-1,LEAVES:0)
Block(-1,8,2,LOG:0)
Block(-2,9,0,LEAVES:0)
Block(-2,8,0,LEAVES:0)
Block(4,11,0,LEAVES:0)
Block(-2,7,0,LEAVES:0)
Block(-2,6,0,LEAVES:0)
Block(-2,5,0,LEAVES:0)
Block(4,10,0,LEAVES:0)
Block(1,10,-4,LEAVES:0)
Block(4,9,0,LEAVES:0)
Block(0,8,1,LEAVES:0)
Block(2,9,-1,LEAVES:0)
Block(0,7,1,LEAVES:0)
Block(2,8,-1,LEAVES:0)
Block(0,9,1,LEAVES:0)
Block(-1,10,0,LEAVES:0)
Block(-1,11,0,LEAVES:0)
Block(-1,12,0,LEAVES:0)
Block(-1,13,0,LEAVES:0)
Block(-1,14,0,LEAVES:0)
Block(2,12,2,LEAVES:0)
Block(2,11,2,LOG:0)
Block(2,10,2,LOG:0)
Block(1,9,-1,LEAVES:0)
Block(1,7,-1,LEAVES:0)
Block(1,8,-1,LEAVES:0)
Block(1,5,-1,LEAVES:0)
Block(1,6,-1,LEAVES:0)
Block(3,10,1,LEAVES:0)
Block(3,11,1,LEAVES:0)
Block(-5,9,-1,LEAVES:0)
Block(-1,6,1,LOG:0)
Block(-1,5,1,LEAVES:0)
Block(-1,8,1,LEAVES:0)
Block(-1,7,1,LEAVES:0)
Block(-1,9,1,LEAVES:0)
Block(-1,9,-4,LEAVES:0)
Block(1,10,3,LOG:0)
Block(0,10,-5,LEAVES:0)
Block(1,11,3,LEAVES:0)
Block(0,9,0,LEAVES:0)
Block(0,11,4,LEAVES:0)
Block(0,8,0,LEAVES:0)
Block(2,9,-2,LEAVES:0)
Block(0,10,4,LEAVES:0)
Block(0,6,-4,LEAVES:0)
Block(1,9,0,LEAVES:0)
Block(-1,10,4,LOG:0)
Block(0,8,-4,LOG:0)
Block(1,8,0,LEAVES:0)
Block(0,7,-4,LOG:0)
Block(1,7,0,LOG:0)
Block(-2,9,-3,LOG:0)
Block(0,14,1,LEAVES:0)
Block(-2,8,-3,LOG:0)
Block(1,10,-3,LEAVES:0)
Block(2,10,-2,LEAVES:0)
Block(0,13,1,LEAVES:0)
Block(-2,7,-3,LOG:0)
Block(1,10,4,LEAVES:0)
Block(0,12,1,LEAVES:0)
Block(-3,7,0,LEAVES:0)
Block(-3,6,0,LEAVES:0)
Block(0,9,-4,LOG:0)
Block(0,10,-4,LOG:0)
Block(-3,8,0,LEAVES:0)
Block(0,11,-4,LEAVES:0)
Block(-2,6,-3,LEAVES:0)
Block(0,11,1,LEAVES:0)
Block(0,10,1,LEAVES:0)
Block(-3,5,0,LEAVES:0)
Block(-2,9,2,LOG:0)
Block(-2,8,2,LEAVES:0)
Block(-1,9,4,LOG:0)
Block(-2,7,2,LEAVES:0)
Block(-1,8,4,LEAVES:0)
Block(-1,10,-2,LEAVES:0)
Block(-1,11,-2,LEAVES:0)
Block(0,8,3,LEAVES:0)
Block(-1,11,4,LOG:0)
Block(-1,12,4,LEAVES:0)
Block(0,9,3,LEAVES:0)
Block(1,9,1,LEAVES:0)
Block(1,8,1,LOG:8)
Block(0,6,1,LEAVES:0)
Block(0,7,-5,LEAVES:0)
Block(1,7,1,LEAVES:0)
Block(0,5,1,LEAVES:0)
Block(1,6,1,LEAVES:0)
Block(-2,12,-1,LEAVES:0)
Block(-2,13,-1,LEAVES:0)
Block(-2,10,-1,LEAVES:0)
Block(-1,10,-1,LOG:0)
Block(-2,11,-1,LEAVES:0)
Block(-2,7,-4,LEAVES:0)
Block(-2,8,-4,LEAVES:0)
Block(-2,9,-4,LEAVES:0)
Block(0,9,-5,LEAVES:0)
Block(0,8,-5,LEAVES:0)
Block(2,11,1,LEAVES:0)
Block(2,10,1,LEAVES:0)
Block(-4,9,-2,LEAVES:0)
Block(-1,10,5,LEAVES:0)
Block(-1,11,5,LEAVES:0)
Block(-1,8,3,LOG:8)
Block(-1,7,3,LEAVES:0)
Block(-2,9,1,LEAVES:0)
Block(-2,8,1,LEAVES:0)
Block(-1,9,3,LEAVES:0)
Block(-2,6,1,LEAVES:0)
Block(-2,10,1,LEAVES:0)
Block(-1,11,-1,LOG:0)
Block(-1,12,-1,LOG:0)
Block(-2,12,1,LEAVES:0)
Block(-1,13,-1,LOG:0)
Block(-2,11,1,LEAVES:0)
Block(-1,14,-1,LEAVES:0)
Block(0,14,0,LOG:0)
Block(0,13,0,LOG:0)
Block(0,12,0,LOG:0)
Block(0,11,0,LOG:0)
Block(0,15,0,LEAVES:0)
Block(1,6,0,LOG:0)
Block(0,7,2,LEAVES:0)
Block(1,5,0,LEAVES:0)
Block(0,9,2,LEAVES:0)
Block(0,8,2,LEAVES:0)
Block(0,10,0,LOG:0)
Block(3,11,0,LOG:0)
Block(3,10,0,LOG:0)
Block(3,12,0,LEAVES:0)
Block(2,10,0,LEAVES:0)
Block(0,6,-2,LEAVES:0)
Block(3,9,-1,LEAVES:0)
Block(2,11,0,LEAVES:0)
Block(-4,9,0,LEAVES:0)
Block(1,9,2,LEAVES:0)
Block(0,8,-2,LOG:4)
Block(1,8,2,LOG:8)
Block(0,7,-2,LEAVES:0)
Block(0,9,-2,LEAVES:0)
Block(-2,10,-2,LEAVES:0)
Block(-2,10,3,LEAVES:0)
Block(-2,9,-1,LEAVES:0)
Block(2,7,0,LEAVES:0)
Block(-3,9,2,LEAVES:0)
Block(2,6,0,LEAVES:0)
Block(2,9,0,LEAVES:0)
Block(2,8,0,LOG:4)
Block(-2,4,-1,LOG:4)
Block(-2,8,-1,LEAVES:0)
Block(-2,7,-1,LEAVES:0)
Block(-2,6,-1,LEAVES:0)
Block(-2,5,-1,LEAVES:0)
Block(-1,7,-1,LEAVES:0)
Block(-1,6,-1,LOG:8)
Block(-1,5,-1,LOG:0)
Block(-1,4,-1,LOG:0)
Block(-1,3,-1,LOG:0)
Block(-1,2,-1,LOG:0)
Block(-2,9,4,LEAVES:0)
Block(1,14,0,LEAVES:0)
Block(-1,1,-1,LOG:0)
Block(1,13,0,LEAVES:0)
Block(-1,0,-1,LOG:0)
Block(1,12,0,LEAVES:0)
Block(1,11,0,LEAVES:0)
Block(1,10,0,LEAVES:0)
Block(-1,9,-1,LEAVES:0)
Block(-2,11,3,LEAVES:0)
Block(-1,8,-1,LOG:8)
Block(-2,12,3,LEAVES:0)
Block(2,10,-1,LEAVES:0)
Block(-4,10,0,LEAVES:0)
Block(-4,11,0,LEAVES:0)
Block(-3,10,-1,LEAVES:0)
Block(0,10,2,LEAVES:0)
Block(-3,9,-4,LEAVES:0)
Block(-3,11,-1,LEAVES:0)
Block(0,11,2,LEAVES:0)
Block(0,10,-3,LEAVES:0)
Block(-4,11,-2,LEAVES:0)
Block(-4,10,-2,LEAVES:0)
Block(-5,11,-1,LEAVES:0)
Block(1,9,3,LOG:0)
Block(1,8,3,LEAVES:0)
Block(0,7,-3,LEAVES:0)
Block(0,6,-3,LOG:8)
Block(0,9,-3,LEAVES:0)
Block(-5,10,-1,LEAVES:0)
Block(0,8,-3,LEAVES:0)
Block(-1,12,-2,LEAVES:0)
Block(-2,12,2,LOG:0)
Block(-1,13,-2,LEAVES:0)
Block(-2,13,2,LEAVES:0)
Block(1,9,-5,LEAVES:0)
Block(-2,10,2,LOG:0)
Block(-2,11,2,LOG:0)
Block(2,9,1,LEAVES:0)
Block(-2,9,-2,LEAVES:0)
Block(-2,8,-2,LEAVES:0)
Block(2,8,1,LEAVES:0)
Block(-1,11,3,LEAVES:0)
Block(-1,10,3,LEAVES:0)
Block(-2,7,-2,LEAVES:0)
Block(-2,6,-2,LEAVES:0)
Block(-2,5,-2,LEAVES:0)
Block(-2,9,3,LEAVES:0)
Block(-2,8,3,LEAVES:0)
Block(3,10,-1,LEAVES:0)
Block(-1,9,5,LEAVES:0)
Block(3,11,-1,LEAVES:0)
Block(1,10,-2,LOG:0)
Block(1,11,-2,LEAVES:0)
Block(-3,7,-3,LEAVES:0)
Block(-3,8,-3,LEAVES:0)
Block(-3,9,-3,LEAVES:0)
Block(0,9,4,LEAVES:0)

#######################################################################
# +-----------------------------------------------------------------+ #
# |                            BO3 checks                           | #
# +-----------------------------------------------------------------+ #
#######################################################################

BlockCheck(-1,-1,-1,GRASS:0,DIRT:0,DIRT:2)

#######################################################################
# +-----------------------------------------------------------------+ #
# |                             Branches                            | #
# +-----------------------------------------------------------------+ #
#######################################################################


#######################################################################
# +-----------------------------------------------------------------+ #
# |                             Entities                            | #
# +-----------------------------------------------------------------+ #
#######################################################################


#######################################################################
# +-----------------------------------------------------------------+ #
# |                            Particles                            | #
# +-----------------------------------------------------------------+ #
#######################################################################


#######################################################################
# +-----------------------------------------------------------------+ #
# |                             Spawners                            | #
# +-----------------------------------------------------------------+ #
#######################################################################


#######################################################################
# +-----------------------------------------------------------------+ #
# |                             ModData                             | #
# +-----------------------------------------------------------------+ #
#######################################################################

