
#######################################################################
# +-----------------------------------------------------------------+ #
# |                            BO3 object                           | #
# +-----------------------------------------------------------------+ #
#######################################################################

Author: Unknown

Description: Converted version of the BO2 AcaciaSavanna7

Version: 3

SettingsMode: WriteWithoutComments


#######################################################################
# +-----------------------------------------------------------------+ #
# |                          Main settings                          | #
# +-----------------------------------------------------------------+ #
#######################################################################

Tree: true

Frequency: 1

Rarity: 5.0

RotateRandomly: true

SpawnHeight: highestSolidBlock

SpawnHeightOffset: 0

SpawnHeightVariance: 0

##############################
# Height Limits for the BO3. #
##############################

MinHeight: 62

MaxHeight: 210

######################
# Extrusion settings #
######################

ExtrudeMode: None

ExtrudeThroughBlocks: AIR

MaxBranchDepth: 10

ExcludedBiomes: All


#######################################################################
# +-----------------------------------------------------------------+ #
# |                      Source block settings                      | #
# +-----------------------------------------------------------------+ #
#######################################################################

SourceBlocks: STONE:1,STONE:3,STONE:5,DIRT:1,DIRT:0,SAND:0,GRASS:0,DIRT:2,STATIONARY_WATER:0,HARD_CLAY,STAINED_CLAY:0,CLAY,SANDSTONE:0,SAND:1,AIR,STONE:0,GRAVEL,LONG_GRASS:0,LONG_GRASS:1,LONG_GRASS:2,DEAD_BUSH,YELLOW_FLOWER:0,RED_ROSE:0,BROWN_MUSHROOM,RED_MUSHROOM

MaxPercentageOutsideSourceBlock: 0

OutsideSourceBlock: placeAnyway

IsOTGPlus: false


#######################################################################
# +-----------------------------------------------------------------+ #
# |                              Blocks                             | #
# +-----------------------------------------------------------------+ #
#######################################################################

Block(3,7,-3,LEAVES_2:8)
Block(-4,8,2,LEAVES_2:8)
Block(-4,7,2,LEAVES_2:8)
Block(1,7,4,LEAVES_2:8)
Block(3,8,-3,LEAVES_2:8)
Block(1,8,-4,LEAVES_2:8)
Block(2,8,2,LEAVES_2:8)
Block(1,7,-4,LEAVES_2:8)
Block(-3,7,4,LEAVES_2:8)
Block(2,7,2,LEAVES_2:8)
Block(-5,7,-2,LEAVES_2:8)
Block(-5,8,-2,LEAVES_2:8)
Block(3,8,0,LEAVES_2:8)
Block(3,7,0,LEAVES_2:8)
Block(3,6,0,LEAVES_2:8)
Block(-1,7,0,LEAVES_2:8)
Block(-1,6,0,LEAVES_2:8)
Block(-1,9,0,LEAVES_2:8)
Block(-1,8,0,LEAVES_2:8)
Block(3,9,0,LEAVES_2:8)
Block(-1,8,-3,LEAVES_2:8)
Block(-1,7,-3,LEAVES_2:8)
Block(-1,6,-3,LEAVES_2:8)
Block(-3,6,-2,LEAVES_2:8)
Block(-3,7,-2,LEAVES_2:8)
Block(-3,8,-2,LEAVES_2:8)
Block(-3,9,-2,LEAVES_2:8)
Block(0,5,-1,LOG_2:0)
Block(3,6,-2,LEAVES_2:8)
Block(3,7,-2,LEAVES_2:8)
Block(0,7,-1,LEAVES_2:8)
Block(3,8,-2,LEAVES_2:8)
Block(0,6,-1,LEAVES_2:8)
Block(-4,8,1,LEAVES_2:8)
Block(0,9,-1,LEAVES_2:8)
Block(0,8,-1,LEAVES_2:8)
Block(6,7,0,LEAVES_2:8)
Block(-4,7,1,LEAVES_2:8)
Block(2,7,3,LEAVES_2:8)
Block(1,7,-3,LEAVES_2:8)
Block(1,8,-3,LEAVES_2:8)
Block(-3,8,3,LEAVES_2:8)
Block(1,6,-3,LEAVES_2:8)
Block(-3,7,3,LEAVES_2:8)
Block(-5,7,-3,LEAVES_2:8)
Block(-1,6,-2,LEAVES_2:8)
Block(3,7,1,LEAVES_2:8)
Block(-2,7,5,LEAVES_2:8)
Block(3,8,1,LEAVES_2:8)
Block(-1,9,-2,LEAVES_2:8)
Block(-1,8,-2,LEAVES_2:8)
Block(-1,7,-2,LEAVES_2:8)
Block(-5,8,0,LEAVES_2:8)
Block(-3,6,-1,LEAVES_2:8)
Block(-3,7,-1,LEAVES_2:8)
Block(-3,8,-1,LEAVES_2:8)
Block(-3,9,-1,LEAVES_2:8)
Block(-5,7,0,LEAVES_2:8)
Block(0,7,0,LEAVES_2:8)
Block(0,6,0,LEAVES_2:8)
Block(1,8,-2,LEAVES_2:8)
Block(1,9,-2,LEAVES_2:8)
Block(1,6,-2,LEAVES_2:8)
Block(1,7,-2,LEAVES_2:8)
Block(-2,7,-5,LEAVES_2:8)
Block(-2,8,-5,LEAVES_2:8)
Block(-4,8,-1,LEAVES_2:8)
Block(-4,7,-1,LEAVES_2:8)
Block(-4,9,-1,LEAVES_2:8)
Block(-1,7,2,LOG_2:0)
Block(-1,6,2,LEAVES_2:8)
Block(3,8,2,LEAVES_2:8)
Block(-1,9,2,LEAVES_2:8)
Block(3,7,2,LEAVES_2:8)
Block(-1,8,2,LEAVES_2:8)
Block(-2,9,0,LEAVES_2:8)
Block(-2,8,0,LEAVES_2:8)
Block(-2,7,0,LEAVES_2:8)
Block(-2,6,0,LEAVES_2:8)
Block(-1,7,-5,LEAVES_2:8)
Block(-5,7,1,LEAVES_2:8)
Block(4,7,0,LEAVES_2:8)
Block(4,8,0,LEAVES_2:8)
Block(0,8,1,LEAVES_2:8)
Block(2,9,-1,LEAVES_2:8)
Block(0,7,1,LEAVES_2:8)
Block(2,8,-1,LEAVES_2:8)
Block(2,7,-1,LEAVES_2:8)
Block(2,6,-1,LOG_2:0)
Block(0,9,1,LEAVES_2:8)
Block(-4,7,3,LEAVES_2:8)
Block(3,7,-4,LEAVES_2:8)
Block(1,9,-1,LEAVES_2:8)
Block(1,7,-1,LEAVES_2:8)
Block(1,8,-1,LEAVES_2:8)
Block(1,5,-1,LOG_2:0)
Block(1,6,-1,LEAVES_2:8)
Block(-2,7,-6,LEAVES_2:8)
Block(1,3,-1,LOG_2:0)
Block(1,4,-1,LOG_2:0)
Block(-5,7,-1,LEAVES_2:8)
Block(1,1,-1,LOG_2:0)
Block(1,2,-1,LOG_2:0)
Block(1,0,-1,LOG_2:0)
Block(-5,8,-1,LEAVES_2:8)
Block(-1,6,1,LEAVES_2:8)
Block(-1,8,1,LEAVES_2:8)
Block(-1,7,1,LEAVES_2:8)
Block(3,7,3,LEAVES_2:8)
Block(-1,9,1,LEAVES_2:8)
Block(-1,8,-4,LEAVES_2:8)
Block(-1,7,-4,LEAVES_2:8)
Block(-6,7,0,LEAVES_2:8)
Block(-5,7,2,LEAVES_2:8)
Block(4,8,1,LEAVES_2:8)
Block(4,7,1,LEAVES_2:8)
Block(2,8,-2,LEAVES_2:8)
Block(0,9,0,LEAVES_2:8)
Block(2,7,-2,LEAVES_2:8)
Block(0,8,0,LEAVES_2:8)
Block(2,6,-2,LEAVES_2:8)
Block(2,9,-2,LEAVES_2:8)
Block(1,9,0,LEAVES_2:8)
Block(1,8,0,LEAVES_2:8)
Block(0,7,-4,LEAVES_2:8)
Block(1,7,0,LEAVES_2:8)
Block(-6,7,-2,LEAVES_2:8)
Block(-2,9,-3,LEAVES_2:8)
Block(-2,8,-3,LEAVES_2:8)
Block(-2,7,-3,LEAVES_2:8)
Block(4,7,-3,LEAVES_2:8)
Block(-3,7,0,LEAVES_2:8)
Block(-3,9,0,LEAVES_2:8)
Block(-3,8,0,LEAVES_2:8)
Block(-2,6,-3,LEAVES_2:8)
Block(-4,8,-3,LEAVES_2:8)
Block(-4,7,-3,LEAVES_2:8)
Block(-1,7,4,LEAVES_2:8)
Block(-2,8,2,LEAVES_2:8)
Block(-2,7,2,LEAVES_2:8)
Block(-1,8,4,LEAVES_2:8)
Block(-2,6,2,LEAVES_2:8)
Block(4,7,2,LEAVES_2:8)
Block(2,7,-3,LEAVES_2:8)
Block(2,6,-3,LEAVES_2:8)
Block(-3,7,-6,LEAVES_2:8)
Block(5,8,0,LEAVES_2:8)
Block(0,8,3,LEAVES_2:8)
Block(5,7,0,LEAVES_2:8)
Block(0,7,3,LEAVES_2:8)
Block(2,8,-3,LEAVES_2:8)
Block(6,7,-1,LEAVES_2:8)
Block(1,9,1,LEAVES_2:8)
Block(1,8,1,LEAVES_2:8)
Block(0,6,1,LOG_2:0)
Block(1,7,1,LEAVES_2:8)
Block(1,6,1,LEAVES_2:8)
Block(-6,7,-1,LEAVES_2:8)
Block(4,8,-2,LEAVES_2:8)
Block(-2,7,-4,LEAVES_2:8)
Block(4,7,-2,LEAVES_2:8)
Block(-2,8,-4,LEAVES_2:8)
Block(-4,7,-2,LEAVES_2:8)
Block(-4,8,-2,LEAVES_2:8)
Block(-1,8,3,LEAVES_2:8)
Block(-1,7,3,LEAVES_2:8)
Block(-2,9,1,LEAVES_2:8)
Block(-2,8,1,LEAVES_2:8)
Block(-2,7,1,LEAVES_2:8)
Block(-2,6,1,LEAVES_2:8)
Block(1,6,0,LEAVES_2:8)
Block(0,7,2,LEAVES_2:8)
Block(1,5,0,LOG_2:0)
Block(0,6,2,LEAVES_2:8)
Block(-3,7,-5,LEAVES_2:8)
Block(5,7,1,LEAVES_2:8)
Block(-3,8,-5,LEAVES_2:8)
Block(0,9,2,LEAVES_2:8)
Block(0,8,2,LEAVES_2:8)
Block(2,8,-4,LEAVES_2:8)
Block(2,7,-4,LEAVES_2:8)
Block(3,7,-1,LOG_2:0)
Block(3,8,-1,LEAVES_2:8)
Block(0,6,-2,LEAVES_2:8)
Block(3,9,-1,LEAVES_2:8)
Block(0,8,-2,LEAVES_2:8)
Block(1,8,2,LEAVES_2:8)
Block(0,7,-2,LEAVES_2:8)
Block(1,7,2,LEAVES_2:8)
Block(1,6,2,LEAVES_2:8)
Block(-4,8,0,LEAVES_2:8)
Block(-4,7,0,LEAVES_2:8)
Block(3,6,-1,LEAVES_2:8)
Block(-2,9,-1,LEAVES_2:8)
Block(2,7,0,LEAVES_2:8)
Block(2,6,0,LEAVES_2:8)
Block(4,8,-1,LEAVES_2:8)
Block(-3,8,2,LEAVES_2:8)
Block(2,9,0,LEAVES_2:8)
Block(2,8,0,LEAVES_2:8)
Block(4,7,-1,LEAVES_2:8)
Block(-3,7,2,LEAVES_2:8)
Block(4,6,-1,LEAVES_2:8)
Block(-5,7,-4,LEAVES_2:8)
Block(-2,8,-1,LEAVES_2:8)
Block(-2,7,-1,LEAVES_2:8)
Block(-2,6,-1,LEAVES_2:8)
Block(-1,7,-1,LEAVES_2:8)
Block(-1,6,-1,LOG_2:0)
Block(-2,8,4,LEAVES_2:8)
Block(-2,7,4,LEAVES_2:8)
Block(-4,7,-5,LEAVES_2:8)
Block(-1,9,-1,LEAVES_2:8)
Block(-1,8,-1,LEAVES_2:8)
Block(5,7,-1,LEAVES_2:8)
Block(5,8,-1,LEAVES_2:8)
Block(-3,7,-4,LEAVES_2:8)
Block(-3,8,-4,LEAVES_2:8)
Block(0,7,5,LEAVES_2:8)
Block(2,7,-5,LEAVES_2:8)
Block(1,8,3,LEAVES_2:8)
Block(0,7,-3,LEAVES_2:8)
Block(1,7,3,LEAVES_2:8)
Block(0,8,-3,LEAVES_2:8)
Block(1,7,-5,LEAVES_2:8)
Block(-2,9,-2,LEAVES_2:8)
Block(-2,8,-2,LEAVES_2:8)
Block(2,6,1,LEAVES_2:8)
Block(2,8,1,LEAVES_2:8)
Block(2,7,1,LEAVES_2:8)
Block(-3,6,1,LEAVES_2:8)
Block(-3,8,1,LEAVES_2:8)
Block(-3,7,1,LEAVES_2:8)
Block(-2,7,-2,LOG_2:0)
Block(-2,6,-2,LEAVES_2:8)
Block(-4,7,-4,LEAVES_2:8)
Block(-2,8,3,LEAVES_2:8)
Block(-2,7,3,LEAVES_2:8)
Block(-1,7,5,LEAVES_2:8)
Block(-4,8,-4,LEAVES_2:8)
Block(5,7,-2,LEAVES_2:8)
Block(-3,7,-3,LEAVES_2:8)
Block(-3,8,-3,LEAVES_2:8)
Block(0,7,4,LEAVES_2:8)
Block(0,8,4,LEAVES_2:8)

#######################################################################
# +-----------------------------------------------------------------+ #
# |                            BO3 checks                           | #
# +-----------------------------------------------------------------+ #
#######################################################################

BlockCheck(1,-1,-1,GRASS:0,DIRT:0,DIRT:2)

#######################################################################
# +-----------------------------------------------------------------+ #
# |                             Branches                            | #
# +-----------------------------------------------------------------+ #
#######################################################################


#######################################################################
# +-----------------------------------------------------------------+ #
# |                             Entities                            | #
# +-----------------------------------------------------------------+ #
#######################################################################


#######################################################################
# +-----------------------------------------------------------------+ #
# |                            Particles                            | #
# +-----------------------------------------------------------------+ #
#######################################################################


#######################################################################
# +-----------------------------------------------------------------+ #
# |                             Spawners                            | #
# +-----------------------------------------------------------------+ #
#######################################################################


#######################################################################
# +-----------------------------------------------------------------+ #
# |                             ModData                             | #
# +-----------------------------------------------------------------+ #
#######################################################################

