
#######################################################################
# +-----------------------------------------------------------------+ #
# |                            BO3 object                           | #
# +-----------------------------------------------------------------+ #
#######################################################################

Author: Unknown

Description: Converted version of the BO2 AcaciaSavanna8

Version: 3

SettingsMode: WriteWithoutComments


#######################################################################
# +-----------------------------------------------------------------+ #
# |                          Main settings                          | #
# +-----------------------------------------------------------------+ #
#######################################################################

Tree: true

Frequency: 1

Rarity: 5.0

RotateRandomly: true

SpawnHeight: highestSolidBlock

SpawnHeightOffset: 0

SpawnHeightVariance: 0

##############################
# Height Limits for the BO3. #
##############################

MinHeight: 62

MaxHeight: 210

######################
# Extrusion settings #
######################

ExtrudeMode: None

ExtrudeThroughBlocks: AIR

MaxBranchDepth: 10

ExcludedBiomes: All


#######################################################################
# +-----------------------------------------------------------------+ #
# |                      Source block settings                      | #
# +-----------------------------------------------------------------+ #
#######################################################################

SourceBlocks: STONE:1,STONE:3,STONE:5,DIRT:1,DIRT:0,SAND:0,GRASS:0,DIRT:2,STATIONARY_WATER:0,HARD_CLAY,STAINED_CLAY:0,CLAY,SANDSTONE:0,SAND:1,AIR,STONE:0,GRAVEL,LONG_GRASS:0,LONG_GRASS:1,LONG_GRASS:2,DEAD_BUSH,YELLOW_FLOWER:0,RED_ROSE:0,BROWN_MUSHROOM,RED_MUSHROOM

MaxPercentageOutsideSourceBlock: 0

OutsideSourceBlock: placeAnyway

IsOTGPlus: false


#######################################################################
# +-----------------------------------------------------------------+ #
# |                              Blocks                             | #
# +-----------------------------------------------------------------+ #
#######################################################################

Block(-4,6,2,LEAVES_2:8)
Block(-4,5,2,LEAVES_2:8)
Block(1,8,-4,LEAVES_2:8)
Block(1,6,-4,LEAVES_2:8)
Block(1,7,-4,LEAVES_2:8)
Block(1,5,-4,LEAVES_2:8)
Block(-3,6,4,LEAVES_2:8)
Block(-2,5,-7,LEAVES_2:8)
Block(-3,5,4,LEAVES_2:8)
Block(-7,6,-1,LEAVES_2:8)
Block(-2,6,6,LEAVES_2:8)
Block(-2,5,6,LEAVES_2:8)
Block(-1,5,8,LEAVES_2:8)
Block(-3,4,-2,LEAVES_2:8)
Block(-3,5,-2,LEAVES_2:8)
Block(5,6,-3,LEAVES_2:8)
Block(-3,6,-2,LEAVES_2:8)
Block(5,5,4,LEAVES_2:8)
Block(-7,5,-1,LEAVES_2:8)
Block(-6,5,-5,LEAVES_2:8)
Block(-4,7,1,LEAVES_2:8)
Block(-4,6,1,LEAVES_2:8)
Block(-4,5,1,LEAVES_2:8)
Block(-4,4,1,LEAVES_2:8)
Block(1,7,-3,LEAVES_2:8)
Block(1,8,-3,LEAVES_2:8)
Block(1,5,-3,LEAVES_2:8)
Block(1,6,-3,LEAVES_2:8)
Block(-3,4,3,LEAVES_2:8)
Block(-3,6,3,LEAVES_2:8)
Block(-3,5,3,LEAVES_2:8)
Block(-7,5,-2,LEAVES_2:8)
Block(-2,7,5,LEAVES_2:8)
Block(-2,6,5,LEAVES_2:8)
Block(-2,5,5,LEAVES_2:8)
Block(-1,6,7,LEAVES_2:8)
Block(-1,5,7,LEAVES_2:8)
Block(-3,5,-1,LEAVES_2:8)
Block(-3,6,-1,LEAVES_2:8)
Block(-3,7,-1,LEAVES_2:8)
Block(-5,5,0,LEAVES_2:8)
Block(-5,4,0,LEAVES_2:8)
Block(-5,6,0,LEAVES_2:8)
Block(-4,6,4,LEAVES_2:8)
Block(-4,5,4,LEAVES_2:8)
Block(0,5,0,LEAVES_2:8)
Block(0,6,-6,LEAVES_2:8)
Block(0,6,0,LEAVES_2:8)
Block(-6,5,-4,LEAVES_2:8)
Block(1,8,-2,LEAVES_2:8)
Block(-2,5,-5,LEAVES_2:8)
Block(-3,5,6,LEAVES_2:8)
Block(1,6,-2,LEAVES_2:8)
Block(-2,6,-5,LEAVES_2:8)
Block(1,7,-2,LEAVES_2:8)
Block(1,5,-2,LOG_2:0)
Block(4,6,-5,LEAVES_2:8)
Block(-3,6,6,LEAVES_2:8)
Block(-4,7,-1,LEAVES_2:8)
Block(-4,4,-1,LOG_2:0)
Block(-7,5,-3,LEAVES_2:8)
Block(-2,5,8,LEAVES_2:8)
Block(-4,6,-1,LEAVES_2:8)
Block(-4,5,-1,LEAVES_2:8)
Block(2,5,-1,LEAVES_2:8)
Block(2,7,-1,LEAVES_2:8)
Block(2,6,-1,LEAVES_2:8)
Block(-5,6,1,LEAVES_2:8)
Block(-5,5,1,LEAVES_2:8)
Block(-4,6,3,LEAVES_2:8)
Block(-4,5,3,LEAVES_2:8)
Block(-6,6,-3,LEAVES_2:8)
Block(-6,5,-3,LEAVES_2:8)
Block(4,6,-4,LEAVES_2:8)
Block(-3,6,5,LEAVES_2:8)
Block(1,7,-1,LEAVES_2:8)
Block(-2,5,-6,LEAVES_2:8)
Block(-3,5,5,LEAVES_2:8)
Block(1,6,-1,LEAVES_2:8)
Block(-6,6,0,LEAVES_2:8)
Block(-6,5,0,LEAVES_2:8)
Block(-2,6,7,LEAVES_2:8)
Block(-7,5,-4,LEAVES_2:8)
Block(-2,5,7,LEAVES_2:8)
Block(-5,6,2,LEAVES_2:8)
Block(2,8,-2,LEAVES_2:8)
Block(2,7,-2,LEAVES_2:8)
Block(2,6,-2,LEAVES_2:8)
Block(2,5,-2,LEAVES_2:8)
Block(-5,5,2,LEAVES_2:8)
Block(-4,5,6,LEAVES_2:8)
Block(0,6,-4,LEAVES_2:8)
Block(0,7,-4,LEAVES_2:8)
Block(2,5,6,LEAVES_2:8)
Block(-2,7,-3,LEAVES_2:8)
Block(-2,6,-3,LEAVES_2:8)
Block(-2,5,-3,LEAVES_2:8)
Block(-2,4,-3,LOG_2:0)
Block(-6,5,1,LEAVES_2:8)
Block(-4,6,-3,LEAVES_2:8)
Block(-4,5,-3,LEAVES_2:8)
Block(-4,4,-3,LEAVES_2:8)
Block(3,6,4,LEAVES_2:8)
Block(3,5,4,LEAVES_2:8)
Block(-6,6,1,LEAVES_2:8)
Block(-5,6,3,LEAVES_2:8)
Block(-5,5,3,LEAVES_2:8)
Block(4,5,2,LEAVES_2:8)
Block(4,6,2,LEAVES_2:8)
Block(2,7,-3,LEAVES_2:8)
Block(2,6,-3,LOG_2:0)
Block(2,5,-3,LEAVES_2:8)
Block(2,8,-3,LEAVES_2:8)
Block(-4,6,5,LEAVES_2:8)
Block(-4,5,5,LEAVES_2:8)
Block(0,7,-5,LEAVES_2:8)
Block(0,6,-5,LEAVES_2:8)
Block(-7,5,0,LEAVES_2:8)
Block(-2,6,-4,LEAVES_2:8)
Block(-3,5,7,LEAVES_2:8)
Block(-2,4,-4,LEAVES_2:8)
Block(-2,5,-4,LEAVES_2:8)
Block(-7,6,0,LEAVES_2:8)
Block(-4,7,-2,LEAVES_2:8)
Block(-4,6,-2,LEAVES_2:8)
Block(-4,5,-2,LEAVES_2:8)
Block(3,5,5,LEAVES_2:8)
Block(-4,4,-2,LEAVES_2:8)
Block(-1,5,-6,LEAVES_2:8)
Block(-6,6,2,LEAVES_2:8)
Block(-6,5,2,LEAVES_2:8)
Block(-5,5,4,LEAVES_2:8)
Block(-5,6,4,LEAVES_2:8)
Block(4,6,3,LEAVES_2:8)
Block(4,5,3,LEAVES_2:8)
Block(2,6,-4,LEAVES_2:8)
Block(5,5,1,LEAVES_2:8)
Block(2,7,-4,LEAVES_2:8)
Block(3,7,-1,LEAVES_2:8)
Block(0,6,-2,LEAVES_2:8)
Block(0,5,-2,LEAVES_2:8)
Block(0,7,-2,LEAVES_2:8)
Block(6,5,3,LEAVES_2:8)
Block(3,6,-1,LEAVES_2:8)
Block(-7,5,1,LEAVES_2:8)
Block(-2,6,-1,LEAVES_2:8)
Block(-2,5,-1,LEAVES_2:8)
Block(-4,6,-5,LEAVES_2:8)
Block(-4,5,-5,LEAVES_2:8)
Block(3,5,6,LEAVES_2:8)
Block(-6,5,3,LEAVES_2:8)
Block(-5,5,5,LEAVES_2:8)
Block(4,5,4,LEAVES_2:8)
Block(5,5,2,LEAVES_2:8)
Block(2,7,-5,LEAVES_2:8)
Block(2,6,-5,LEAVES_2:8)
Block(-4,5,7,LEAVES_2:8)
Block(0,5,-3,LEAVES_2:8)
Block(0,7,-3,LEAVES_2:8)
Block(0,6,-3,LEAVES_2:8)
Block(0,8,-3,LEAVES_2:8)
Block(6,5,2,LEAVES_2:8)
Block(-8,5,0,LEAVES_2:8)
Block(-7,5,2,LEAVES_2:8)
Block(-2,6,-2,LEAVES_2:8)
Block(-2,5,-2,LEAVES_2:8)
Block(-4,5,-4,LEAVES_2:8)
Block(-4,6,-4,LEAVES_2:8)
Block(-6,5,4,LEAVES_2:8)
Block(-5,5,6,LEAVES_2:8)
Block(5,6,-2,LEAVES_2:8)
Block(4,5,5,LEAVES_2:8)
Block(5,6,3,LEAVES_2:8)
Block(5,5,3,LEAVES_2:8)
Block(2,6,-6,LEAVES_2:8)
Block(3,6,-3,LEAVES_2:8)
Block(3,7,-3,LEAVES_2:8)
Block(1,7,4,LEAVES_2:8)
Block(1,6,4,LEAVES_2:8)
Block(1,5,4,LEAVES_2:8)
Block(1,4,4,LEAVES_2:8)
Block(2,5,2,LEAVES_2:8)
Block(2,4,2,LEAVES_2:8)
Block(2,7,2,LEAVES_2:8)
Block(2,6,2,LEAVES_2:8)
Block(-5,5,-2,LEAVES_2:8)
Block(-5,6,-2,LEAVES_2:8)
Block(-5,4,-2,LEAVES_2:8)
Block(-5,7,-2,LEAVES_2:8)
Block(-1,5,-3,LEAVES_2:8)
Block(-1,5,0,LEAVES_2:8)
Block(-1,4,0,LEAVES_2:8)
Block(3,6,0,LEAVES_2:8)
Block(3,5,0,LEAVES_2:8)
Block(-1,6,0,LEAVES_2:8)
Block(2,4,1,LEAVES_2:8)
Block(-6,5,5,LEAVES_2:8)
Block(-4,5,-7,LEAVES_2:8)
Block(-1,7,-3,LEAVES_2:8)
Block(-1,6,-3,LEAVES_2:8)
Block(-1,1,0,LOG_2:0)
Block(-1,0,0,LOG_2:0)
Block(0,5,7,LEAVES_2:8)
Block(2,6,-7,LEAVES_2:8)
Block(-1,2,0,LOG_2:0)
Block(0,5,-1,LEAVES_2:8)
Block(3,6,-2,LEAVES_2:8)
Block(0,4,-1,LOG_2:0)
Block(3,7,-2,LEAVES_2:8)
Block(0,7,-1,LEAVES_2:8)
Block(1,7,5,LEAVES_2:8)
Block(0,6,-1,LEAVES_2:8)
Block(1,6,5,LEAVES_2:8)
Block(1,5,5,LEAVES_2:8)
Block(3,5,-2,LEAVES_2:8)
Block(2,7,3,LEAVES_2:8)
Block(2,4,3,LEAVES_2:8)
Block(2,6,3,LEAVES_2:8)
Block(2,5,3,LOG_2:0)
Block(-5,5,-3,LEAVES_2:8)
Block(-5,6,-3,LEAVES_2:8)
Block(-1,6,-2,LEAVES_2:8)
Block(-1,5,-2,LEAVES_2:8)
Block(-4,5,-6,LEAVES_2:8)
Block(3,5,1,LEAVES_2:8)
Block(-1,3,-2,LOG_2:0)
Block(-1,7,-2,LEAVES_2:8)
Block(0,5,6,LEAVES_2:8)
Block(0,6,6,LEAVES_2:8)
Block(1,6,6,LEAVES_2:8)
Block(1,5,6,LEAVES_2:8)
Block(3,6,-5,LEAVES_2:8)
Block(2,7,4,LEAVES_2:8)
Block(2,6,4,LEAVES_2:8)
Block(2,5,4,LEAVES_2:8)
Block(3,6,2,LEAVES_2:8)
Block(3,5,2,LEAVES_2:8)
Block(3,4,2,LEAVES_2:8)
Block(-1,5,2,LEAVES_2:8)
Block(-1,4,2,LEAVES_2:8)
Block(-1,6,2,LEAVES_2:8)
Block(-2,7,0,LEAVES_2:8)
Block(-2,6,0,LEAVES_2:8)
Block(-2,5,0,LEAVES_2:8)
Block(-1,6,-5,LEAVES_2:8)
Block(-1,5,-5,LEAVES_2:8)
Block(-2,2,0,LOG_2:0)
Block(1,5,7,LEAVES_2:8)
Block(3,6,-4,LEAVES_2:8)
Block(3,7,-4,LEAVES_2:8)
Block(2,6,5,LEAVES_2:8)
Block(2,5,5,LEAVES_2:8)
Block(-5,6,-1,LEAVES_2:8)
Block(-5,7,-1,LEAVES_2:8)
Block(-5,4,-1,LEAVES_2:8)
Block(-5,5,-1,LOG_2:0)
Block(-1,4,1,LEAVES_2:8)
Block(3,5,3,LEAVES_2:8)
Block(-1,6,1,LEAVES_2:8)
Block(-1,5,1,LEAVES_2:8)
Block(-1,7,1,LEAVES_2:8)
Block(3,7,3,LEAVES_2:8)
Block(3,6,3,LEAVES_2:8)
Block(-1,7,-4,LEAVES_2:8)
Block(-1,6,-4,LEAVES_2:8)
Block(-1,5,-4,LEAVES_2:8)
Block(4,5,1,LEAVES_2:8)
Block(-3,5,-7,LEAVES_2:8)
Block(0,3,2,LOG_2:0)
Block(0,5,2,LEAVES_2:8)
Block(0,4,2,LEAVES_2:8)
Block(-8,5,-1,LEAVES_2:8)
Block(1,7,0,LEAVES_2:8)
Block(-6,6,-2,LEAVES_2:8)
Block(-6,5,-2,LEAVES_2:8)
Block(4,7,-3,LEAVES_2:8)
Block(4,6,-3,LEAVES_2:8)
Block(-3,7,0,LEAVES_2:8)
Block(-3,6,0,LEAVES_2:8)
Block(-3,3,0,LOG_2:0)
Block(-5,5,-6,LEAVES_2:8)
Block(-3,5,0,LEAVES_2:8)
Block(-3,4,0,LEAVES_2:8)
Block(-1,5,4,LEAVES_2:8)
Block(-1,4,4,LEAVES_2:8)
Block(-1,7,4,LEAVES_2:8)
Block(-1,6,4,LEAVES_2:8)
Block(-2,7,2,LEAVES_2:8)
Block(-2,6,2,LEAVES_2:8)
Block(-2,5,2,LEAVES_2:8)
Block(-2,4,2,LEAVES_2:8)
Block(-3,5,-6,LEAVES_2:8)
Block(0,6,3,LEAVES_2:8)
Block(0,5,3,LEAVES_2:8)
Block(-3,6,-6,LEAVES_2:8)
Block(0,4,1,LEAVES_2:8)
Block(3,6,-6,LEAVES_2:8)
Block(0,3,1,LOG_2:0)
Block(0,6,1,LEAVES_2:8)
Block(0,5,1,LEAVES_2:8)
Block(1,6,1,LEAVES_2:8)
Block(-6,6,-1,LEAVES_2:8)
Block(-6,5,-1,LEAVES_2:8)
Block(-6,4,-1,LEAVES_2:8)
Block(1,6,-7,LEAVES_2:8)
Block(4,6,-2,LEAVES_2:8)
Block(-1,4,3,LOG_2:0)
Block(-1,6,3,LEAVES_2:8)
Block(-1,5,3,LEAVES_2:8)
Block(-2,7,1,LEAVES_2:8)
Block(-2,6,1,LEAVES_2:8)
Block(-2,5,1,LEAVES_2:8)
Block(-2,4,1,LEAVES_2:8)
Block(-3,5,-5,LEAVES_2:8)
Block(-3,6,-5,LEAVES_2:8)
Block(1,6,0,LEAVES_2:8)
Block(1,5,0,LEAVES_2:8)
Block(0,6,2,LEAVES_2:8)
Block(1,4,0,LEAVES_2:8)
Block(1,6,2,LEAVES_2:8)
Block(1,5,2,LEAVES_2:8)
Block(-4,4,0,LEAVES_2:8)
Block(-4,7,0,LEAVES_2:8)
Block(-4,6,0,LEAVES_2:8)
Block(-4,5,0,LEAVES_2:8)
Block(1,6,-6,LEAVES_2:8)
Block(1,7,-6,LEAVES_2:8)
Block(2,7,0,LEAVES_2:8)
Block(2,6,0,LEAVES_2:8)
Block(-3,5,2,LEAVES_2:8)
Block(-3,4,2,LEAVES_2:8)
Block(-3,7,2,LEAVES_2:8)
Block(4,6,-1,LEAVES_2:8)
Block(-3,6,2,LEAVES_2:8)
Block(-5,5,-4,LEAVES_2:8)
Block(-5,6,-4,LEAVES_2:8)
Block(-1,6,-1,LEAVES_2:8)
Block(-1,5,-1,LEAVES_2:8)
Block(-1,3,-1,LOG_2:0)
Block(-1,5,6,LEAVES_2:8)
Block(-2,6,4,LEAVES_2:8)
Block(-1,7,6,LEAVES_2:8)
Block(-2,5,4,LOG_2:0)
Block(-1,6,6,LEAVES_2:8)
Block(-2,4,4,LEAVES_2:8)
Block(-3,4,-4,LEAVES_2:8)
Block(-3,5,-4,LOG_2:0)
Block(-3,6,-4,LEAVES_2:8)
Block(1,5,1,LEAVES_2:8)
Block(1,4,1,LEAVES_2:8)
Block(0,6,5,LEAVES_2:8)
Block(0,5,5,LEAVES_2:8)
Block(0,7,5,LEAVES_2:8)
Block(1,7,3,LEAVES_2:8)
Block(1,6,3,LEAVES_2:8)
Block(0,4,3,LEAVES_2:8)
Block(1,5,3,LEAVES_2:8)
Block(1,4,3,LEAVES_2:8)
Block(1,7,-5,LEAVES_2:8)
Block(1,6,-5,LEAVES_2:8)
Block(2,6,1,LEAVES_2:8)
Block(2,5,1,LEAVES_2:8)
Block(-3,6,1,LEAVES_2:8)
Block(-3,5,1,LEAVES_2:8)
Block(-3,7,1,LEAVES_2:8)
Block(-3,4,1,LEAVES_2:8)
Block(-5,5,-5,LEAVES_2:8)
Block(-1,4,5,LEAVES_2:8)
Block(-1,6,5,LEAVES_2:8)
Block(-1,5,5,LEAVES_2:8)
Block(-2,6,3,LEAVES_2:8)
Block(-1,7,5,LEAVES_2:8)
Block(2,5,0,LEAVES_2:8)
Block(-2,5,3,LEAVES_2:8)
Block(-2,4,3,LEAVES_2:8)
Block(-3,4,-3,LEAVES_2:8)
Block(-3,5,-3,LEAVES_2:8)
Block(-3,6,-3,LEAVES_2:8)
Block(1,4,2,LOG_2:0)
Block(0,5,4,LEAVES_2:8)
Block(0,4,4,LEAVES_2:8)
Block(0,7,4,LEAVES_2:8)
Block(0,6,4,LEAVES_2:8)

#######################################################################
# +-----------------------------------------------------------------+ #
# |                            BO3 checks                           | #
# +-----------------------------------------------------------------+ #
#######################################################################

BlockCheck(-1,-1,0,GRASS:0,DIRT:0,DIRT:2)

#######################################################################
# +-----------------------------------------------------------------+ #
# |                             Branches                            | #
# +-----------------------------------------------------------------+ #
#######################################################################


#######################################################################
# +-----------------------------------------------------------------+ #
# |                             Entities                            | #
# +-----------------------------------------------------------------+ #
#######################################################################


#######################################################################
# +-----------------------------------------------------------------+ #
# |                            Particles                            | #
# +-----------------------------------------------------------------+ #
#######################################################################


#######################################################################
# +-----------------------------------------------------------------+ #
# |                             Spawners                            | #
# +-----------------------------------------------------------------+ #
#######################################################################


#######################################################################
# +-----------------------------------------------------------------+ #
# |                             ModData                             | #
# +-----------------------------------------------------------------+ #
#######################################################################

